Workbook

Sheet Team A
A1: CONSTRUCTION SITE OF THE FUTURE
A2: Human-Robot Collaboration Design Challenge
A4: TEAM A DECISION SHEET
A6: Team Name | B6: Team A
A7: Architecture Lead
A8: Robot Engineer
A9: Cost Manager
A11: PROJECT SCENARIO
A12: Your team has been hired to plan material delivery operations for a new high-rise office building. Construction materials must move from a temporary storage area to multiple work zones. The client wants the work completed quickly, safely, and within budget. Because of labour shortages and interest in automation, your team may combine human workers and construction robots.
A17: PROJECT REQUIREMENTS
A18: Requirement | B18: Value
A19: Project Duration | B19: 5 Days
A20: Total Materials | B20: 100 Units
A21: Required Capacity | B21: 20 Units / Day
A22: Budget Limit | B22: 200 Credits
A24: TEAM ROLES
A25: Role | B25: Focus | C25: Discussion Lens
A26: Architecture Lead | B26: Worker wellbeing; safe site operation; practical implementation | C26: Can this work safely on a real site?
A27: Robot Engineer | B27: Automation; productivity; technical performance | C27: How can robots improve throughput?
A28: Cost Manager | B28: Budget control; resource efficiency | C28: Is the solution affordable and efficient?
A30: AVAILABLE RESOURCES
A31: Human Resources | B31: Cost | C31: Capacity | D31: Support Rule
A32: Construction Worker | B32: 10 | C32: 1 Unit / Day | D32: Workers divide daily capacity between robot support and manual transport.
A35: Robot Resources | B35: Cost | C35: Capacity | D35: Human Support Requirement
A36: Basic Robot | B36: 20 | C36: 3 Units / Day | D36: Uses 0.5 worker-day of support capacity.
A37: Advanced Robot | B37: 35 | C37: 5 Units / Day | D37: Uses 1 worker-day of support capacity.
A38: Autonomous Robot Fleet | B38: 60 | C38: 8 Units / Day | D38: Uses 3 worker-days of support capacity.
A40: ROUND 1 - COST-DRIVEN DESIGN
A41: Client Objective: deliver the project at the lowest possible cost. Select resources, then check whether the solution is feasible.
A44: Resource Selection | B44: Quantity | C44: Notes | F44: Dashboard Results | G44: Auto-Calculated
A45: Construction Workers | C45: Split capacity between support and manual work | F45: Net Daily Capacity (after support) | G45: =IF(COUNT(B45:B48)=0,"",MAX(0,B45-G46)*'Scoring Backend'!$C$4+B46*'Scoring Backend'!$C$6+B47*'Scoring Backend'!$C$7+B48*'Scoring Backend'!$C$8)
A46: Basic Robots | C46: 0.5 worker-day support load per robot | F46: Robot Support Load (Worker-Days) | G46: =IF(COUNT(B45:B48)=0,"",B46*'Scoring Backend'!$G$4+B47*'Scoring Backend'!$G$5+B48*'Scoring Backend'!$G$6)
A47: Advanced Robots | C47: 1 worker-day support load per robot | F47: Human Support Check | G47: =IF(COUNT(B45:B48)=0,"",IF(B45>=G46,"PASS","FAIL"))
A48: Autonomous Fleets | C48: 3 worker-days support load per fleet | F48: Capacity Check | G48: =IF(COUNT(B45:B48)=0,"",IF(G45>='Scoring Backend'!$B$20,"PASS","FAIL"))
F49: Total Cost | G49: =IF(COUNT(B45:B48)=0,"",B45*'Scoring Backend'!$B$4+B46*'Scoring Backend'!$B$6+B47*'Scoring Backend'!$B$7+B48*'Scoring Backend'!$B$8)
A52: Round 1 Team Discussion
A53: Why did your team choose this solution?
A54: What was the most important cost-saving decision?
A55: What practical risk did you consider?
A56: Round 1 Winner Rule | B56: Lowest-cost feasible solution wins.
...

Sheet Scoring Backend
A1: SCORING BACKEND - Editable Workshop Parameters
A3: Resource | B3: Cost | C3: Daily Capacity | D3: Resource Note | F3: SUPPORT COEFFICIENTS | G3: Value | H3: Meaning
A4: Construction Worker | B4: 10 | C4: 1 | D4: Only unassigned workers provide manual transport capacity. | F4: Worker-Day Support Load per Basic Robot | G4: 0.5 | H4: Each Basic Robot uses half of one worker's daily capacity for setup, monitoring, and coordination.
F5: Worker-Day Support Load per Advanced Robot | G5: 1 | H5: Each Advanced Robot uses one worker-day of support capacity.
A6: Basic Robot | B6: 20 | C6: 3 | D6: Robot transport capacity. | F6: Worker-Day Support Load per Autonomous Fleet | G6: 3 | H6: Each fleet uses three worker-days of support capacity.
A7: Advanced Robot | B7: 35 | C7: 5 | D7: Robot transport capacity.
A8: Autonomous Robot Fleet | B8: 60 | C8: 8 | D8: Fleet transport capacity.
A11: HRC Strategy | B11: Cost | C11: Productivity Effect | D11: Safety Effect | E11: Manual Effort Effect | F11: Robot Type | G11: Cost / Unit | H11: Productivity Effect | I11: Safety Effect | J11: Manual Effort Effect
A12: Human-Led | B12: 20 | C12: -5 | D12: -5 | E12: -15 | F12: Basic Robot | G12: 20 | H12: 5 | I12: 5 | J12: 8
A13: Collaborative | B13: 30 | C13: 10 | D13: 10 | E13: 15 | F13: Advanced Robot | G13: 35 | H13: 10 | I13: 10 | J13: 12
A14: Robot-Led | B14: 40 | C14: 20 | D14: 15 | E14: 10 | F14: Autonomous Robot Fleet | G14: 60 | H14: 18 | I14: 8 | J14: 18
A17: Project Parameter | B17: Value | F17: Value Constraint | G17: Value | H17: Metric | I17: Weight | J17: Higher Means
A18: Project Duration (Days) | B18: 5 | F18: Budget Limit | G18: 200 | H18: Productivity | I18: 0.3 | J18: Faster / more efficient task execution
A19: Total Materials (Units) | B19: 100 | F19: Minimum Safety Before Penalty | G19: 70 | H19: Operational Safety | I19: 0.4 | J19: Lower accident or hazardous-event likelihood
A20: Required Capacity (Units / Day) | B20: 20 | H20: Manual Physical Effort Reduction | I20: 0.3 | J20: Less lifting, carrying, fatigue, and strain
A21: Budget Limit (Credits) | B21: 200
A22: Base Productivity Score | B22: 50 | F22: Human-Led Max Robot Capacity Share | G22: 0.35
A23: Base Operational Safety Score | B23: 50 | F23: Collaborative Min Robot Capacity Share | G23: 0.35
A24: Base Manual Physical Effort Reduction Score | B24: 50 | F24: Collaborative Max Robot Capacity Share | G24: 0.75
F25: Robot-Led Min Robot Capacity Share | G25: 0.75
A27: SCORING NOTE
A28: Round 1 resource selections determine capacity, support feasibility, and cost. All human resources use one Construction Worker pool. Robot support is modelled as a worker-day capacity load rather than a headcount. A worker may use part of the day for robot setup, monitoring, and coordination, then use any remaining capacity for manual transport. Basic Robot support uses a 0.5 worker-day-per-robot coefficient. Round 2 follows the Target Value Design model: select one HRC strategy and the same robot types used in Round 1, then compare weighted performance score after budget and safety penalties. The selected HRC strategy must also fit the actual robot capacity share: Human-Led is low robot share, Collaborative is mixed share, and Robot-Led is high robot share. Facilitators may change any yellow backend value before the workshop.

Sheet Team B
A1: CONSTRUCTION SITE OF THE FUTURE
A2: Human-Robot Collaboration Design Challenge
A4: TEAM B DECISION SHEET
A6: Team Name | B6: Team B
A7: Architecture Lead
A8: Robot Engineer
A9: Cost Manager
A11: PROJECT SCENARIO
A12: Your team has been hired to plan material delivery operations for a new high-rise office building. Construction materials must move from a temporary storage area to multiple work zones. The client wants the work completed quickly, safely, and within budget. Because of labour shortages and interest in automation, your team may combine human workers and construction robots.
A17: PROJECT REQUIREMENTS
A18: Requirement | B18: Value
A19: Project Duration | B19: 5 Days
A20: Total Materials | B20: 100 Units
A21: Required Capacity | B21: 20 Units / Day
A22: Budget Limit | B22: 200 Credits
A24: TEAM ROLES
A25: Role | B25: Focus | C25: Discussion Lens
A26: Architecture Lead | B26: Worker wellbeing; safe site operation; practical implementation | C26: Can this work safely on a real site?
A27: Robot Engineer | B27: Automation; productivity; technical performance | C27: How can robots improve throughput?
A28: Cost Manager | B28: Budget control; resource efficiency | C28: Is the solution affordable and efficient?
A30: AVAILABLE RESOURCES
A31: Human Resources | B31: Cost | C31: Capacity | D31: Support Rule
A32: Construction Worker | B32: 10 | C32: 1 Unit / Day | D32: Workers divide daily capacity between robot support and manual transport.
A35: Robot Resources | B35: Cost | C35: Capacity | D35: Human Support Requirement
A36: Basic Robot | B36: 20 | C36: 3 Units / Day | D36: Uses 0.5 worker-day of support capacity.
A37: Advanced Robot | B37: 35 | C37: 5 Units / Day | D37: Uses 1 worker-day of support capacity.
A38: Autonomous Robot Fleet | B38: 60 | C38: 8 Units / Day | D38: Uses 3 worker-days of support capacity.
A40: ROUND 1 - COST-DRIVEN DESIGN
A41: Client Objective: deliver the project at the lowest possible cost. Select resources, then check whether the solution is feasible.
A44: Resource Selection | B44: Quantity | C44: Notes | F44: Dashboard Results | G44: Auto-Calculated
A45: Construction Workers | C45: Split capacity between support and manual work | F45: Net Daily Capacity (after support) | G45: =IF(COUNT(B45:B48)=0,"",MAX(0,B45-G46)*'Scoring Backend'!$C$4+B46*'Scoring Backend'!$C$6+B47*'Scoring Backend'!$C$7+B48*'Scoring Backend'!$C$8)
A46: Basic Robots | C46: 0.5 worker-day support load per robot | F46: Robot Support Load (Worker-Days) | G46: =IF(COUNT(B45:B48)=0,"",B46*'Scoring Backend'!$G$4+B47*'Scoring Backend'!$G$5+B48*'Scoring Backend'!$G$6)
A47: Advanced Robots | C47: 1 worker-day support load per robot | F47: Human Support Check | G47: =IF(COUNT(B45:B48)=0,"",IF(B45>=G46,"PASS","FAIL"))
A48: Autonomous Fleets | C48: 3 worker-days support load per fleet | F48: Capacity Check | G48: =IF(COUNT(B45:B48)=0,"",IF(G45>='Scoring Backend'!$B$20,"PASS","FAIL"))
F49: Total Cost | G49: =IF(COUNT(B45:B48)=0,"",B45*'Scoring Backend'!$B$4+B46*'Scoring Backend'!$B$6+B47*'Scoring Backend'!$B$7+B48*'Scoring Backend'!$B$8)
A52: Round 1 Team Discussion
A53: Why did your team choose this solution?
A54: What was the most important cost-saving decision?
A55: What practical risk did you consider?
A56: Round 1 Winner Rule | B56: Lowest-cost feasible solution wins.
...

Sheet Team C
A1: CONSTRUCTION SITE OF THE FUTURE
A2: Human-Robot Collaboration Design Challenge
A4: TEAM C DECISION SHEET
A6: Team Name | B6: Team C
A7: Architecture Lead
A8: Robot Engineer
A9: Cost Manager
A11: PROJECT SCENARIO
A12: Your team has been hired to plan material delivery operations for a new high-rise office building. Construction materials must move from a temporary storage area to multiple work zones. The client wants the work completed quickly, safely, and within budget. Because of labour shortages and interest in automation, your team may combine human workers and construction robots.
A17: PROJECT REQUIREMENTS
A18: Requirement | B18: Value
A19: Project Duration | B19: 5 Days
A20: Total Materials | B20: 100 Units
A21: Required Capacity | B21: 20 Units / Day
A22: Budget Limit | B22: 200 Credits
A24: TEAM ROLES
A25: Role | B25: Focus | C25: Discussion Lens
A26: Architecture Lead | B26: Worker wellbeing; safe site operation; practical implementation | C26: Can this work safely on a real site?
A27: Robot Engineer | B27: Automation; productivity; technical performance | C27: How can robots improve throughput?
A28: Cost Manager | B28: Budget control; resource efficiency | C28: Is the solution affordable and efficient?
A30: AVAILABLE RESOURCES
A31: Human Resources | B31: Cost | C31: Capacity | D31: Support Rule
A32: Construction Worker | B32: 10 | C32: 1 Unit / Day | D32: Workers divide daily capacity between robot support and manual transport.
A35: Robot Resources | B35: Cost | C35: Capacity | D35: Human Support Requirement
A36: Basic Robot | B36: 20 | C36: 3 Units / Day | D36: Uses 0.5 worker-day of support capacity.
A37: Advanced Robot | B37: 35 | C37: 5 Units / Day | D37: Uses 1 worker-day of support capacity.
A38: Autonomous Robot Fleet | B38: 60 | C38: 8 Units / Day | D38: Uses 3 worker-days of support capacity.
A40: ROUND 1 - COST-DRIVEN DESIGN
A41: Client Objective: deliver the project at the lowest possible cost. Select resources, then check whether the solution is feasible.
A44: Resource Selection | B44: Quantity | C44: Notes | F44: Dashboard Results | G44: Auto-Calculated
A45: Construction Workers | C45: Split capacity between support and manual work | F45: Net Daily Capacity (after support) | G45: =IF(COUNT(B45:B48)=0,"",MAX(0,B45-G46)*'Scoring Backend'!$C$4+B46*'Scoring Backend'!$C$6+B47*'Scoring Backend'!$C$7+B48*'Scoring Backend'!$C$8)
A46: Basic Robots | C46: 0.5 worker-day support load per robot | F46: Robot Support Load (Worker-Days) | G46: =IF(COUNT(B45:B48)=0,"",B46*'Scoring Backend'!$G$4+B47*'Scoring Backend'!$G$5+B48*'Scoring Backend'!$G$6)
A47: Advanced Robots | C47: 1 worker-day support load per robot | F47: Human Support Check | G47: =IF(COUNT(B45:B48)=0,"",IF(B45>=G46,"PASS","FAIL"))
A48: Autonomous Fleets | C48: 3 worker-days support load per fleet | F48: Capacity Check | G48: =IF(COUNT(B45:B48)=0,"",IF(G45>='Scoring Backend'!$B$20,"PASS","FAIL"))
F49: Total Cost | G49: =IF(COUNT(B45:B48)=0,"",B45*'Scoring Backend'!$B$4+B46*'Scoring Backend'!$B$6+B47*'Scoring Backend'!$B$7+B48*'Scoring Backend'!$B$8)
A52: Round 1 Team Discussion
A53: Why did your team choose this solution?
A54: What was the most important cost-saving decision?
A55: What practical risk did you consider?
A56: Round 1 Winner Rule | B56: Lowest-cost feasible solution wins.
...

Sheet Summary
A1: WORKSHOP SUMMARY - TEAM COMPARISON
A3: This dashboard compares Team A, Team B, and Team C. Round 1 rewards the lowest-cost capacity-and-support feasible solution; the budget check remains visible for discussion. Round 2 uses the target value design score: weighted performance minus budget and safety penalties. A team must pass human support, capacity, and HRC strategy-fit checks to be eligible. If tied, the lower-cost solution wins.
A6: Winner Dashboard | B6: Result
A7: Round 1 Winner | B7: =IF(COUNTIF($G$13:$G$15,"YES")=0,"No feasible team yet",INDEX($A$13:$A$15,MATCH(MAX($H$13:$H$15),$H$13:$H$15,0))) -> No feasible team yet
A8: Round 2 Winner | B8: =IF(COUNTIF($O$20:$O$22,"YES")=0,"No eligible team yet",INDEX($A$20:$A$22,MATCH(MAX($P$20:$P$22),$P$20:$P$22,0))) -> No eligible team yet
A9: Round 2 Tie-Breaker | B9: Highest final value score among eligible strategy-fit teams, then lowest cost
A12: Round 1 Comparison | B12: Net Daily Capacity | C12: Human Support | D12: Capacity Check | E12: Budget Check | F12: Total Cost | G12: Feasible? | H12: Winner Score
A13: Team A | B13: =IF('Team A'!G45="","",'Team A'!G45) | C13: =IF('Team A'!G47="","",'Team A'!G47) | D13: =IF('Team A'!G48="","",'Team A'!G48) | E13: =IF('Team A'!G49="","",IF('Team A'!G49<='Scoring Backend'!$B$21,"PASS","FAIL")) | F13: =IF('Team A'!G49="","",'Team A'!G49) | G13: =IF(B13="","",IF(AND(C13="PASS",D13="PASS"),"YES","NO")) | H13: =IF(G13="","",IF(G13="YES",100000-F13,-999999))
A14: Team B | B14: =IF('Team B'!G45="","",'Team B'!G45) | C14: =IF('Team B'!G47="","",'Team B'!G47) | D14: =IF('Team B'!G48="","",'Team B'!G48) | E14: =IF('Team B'!G49="","",IF('Team B'!G49<='Scoring Backend'!$B$21,"PASS","FAIL")) | F14: =IF('Team B'!G49="","",'Team B'!G49) | G14: =IF(B14="","",IF(AND(C14="PASS",D14="PASS"),"YES","NO")) | H14: =IF(G14="","",IF(G14="YES",100000-F14,-999999))
A15: Team C | B15: =IF('Team C'!G45="","",'Team C'!G45) | C15: =IF('Team C'!G47="","",'Team C'!G47) | D15: =IF('Team C'!G48="","",'Team C'!G48) | E15: =IF('Team C'!G49="","",IF('Team C'!G49<='Scoring Backend'!$B$21,"PASS","FAIL")) | F15: =IF('Team C'!G49="","",'Team C'!G49) | G15: =IF(B15="","",IF(AND(C15="PASS",D15="PASS"),"YES","NO")) | H15: =IF(G15="","",IF(G15="YES",100000-F15,-999999))
A19: Round 2 Comparison | B19: Strategy | C19: Net Daily Capacity | D19: Human Support | E19: Capacity Check | F19: Total Cost | G19: Productivity | H19: Operational Safety | I19: Manual Physical Effort Reduction | J19: Performance Score | K19: Budget Penalty | L19: Safety Penalty | M19: Final Value Score | N19: Strategy Fit | O19: Eligible? | P19: Winner Score | Q19: Winner?
A20: Team A | B20: =IF('Team A'!B69="","",'Team A'!B69) | C20: =IF('Team A'!J73="","",'Team A'!J73) | D20: =IF('Team A'!J75="","",'Team A'!J75) | E20: =IF('Team A'!J76="","",'Team A'!J76) | F20: =IF('Team A'!J77="","",'Team A'!J77) | G20: =IF('Team A'!J78="","",'Team A'!J78) | H20: =IF('Team A'!J79="","",'Team A'!J79) | I20: =IF('Team A'!J80="","",'Team A'!J80) | J20: =IF('Team A'!J81="","",'Team A'!J81) | K20: =IF('Team A'!J82="","",'Team A'!J82) | L20: =IF('Team A'!J83="","",'Team A'!J83) | M20: =IF('Team A'!J84="","",'Team A'!J84) | N20: =IF('Team A'!J92="","",'Team A'!J92) | O20: =IF(OR(B20="",D20="",E20="",N20=""),"",IF(AND(D20="PASS",E20="PASS",N20="PASS"),"YES","NO")) | P20: =IF(O20="","",IF(O20="YES",M20*1000-F20,-999999)) | Q20: =IF(P20="","",IF(P20=MAX($P$20:$P$22),"WINNER",""))
A21: Team B | B21: =IF('Team B'!B69="","",'Team B'!B69) | C21: =IF('Team B'!J73="","",'Team B'!J73) | D21: =IF('Team B'!J75="","",'Team B'!J75) | E21: =IF('Team B'!J76="","",'Team B'!J76) | F21: =IF('Team B'!J77="","",'Team B'!J77) | G21: =IF('Team B'!J78="","",'Team B'!J78) | H21: =IF('Team B'!J79="","",'Team B'!J79) | I21: =IF('Team B'!J80="","",'Team B'!J80) | J21: =IF('Team B'!J81="","",'Team B'!J81) | K21: =IF('Team B'!J82="","",'Team B'!J82) | L21: =IF('Team B'!J83="","",'Team B'!J83) | M21: =IF('Team B'!J84="","",'Team B'!J84) | N21: =IF('Team B'!J92="","",'Team B'!J92) | O21: =IF(OR(B21="",D21="",E21="",N21=""),"",IF(AND(D21="PASS",E21="PASS",N21="PASS"),"YES","NO")) | P21: =IF(O21="","",IF(O21="YES",M21*1000-F21,-999999)) | Q21: =IF(P21="","",IF(P21=MAX($P$20:$P$22),"WINNER",""))
A22: Team C | B22: =IF('Team C'!B69="","",'Team C'!B69) | C22: =IF('Team C'!J73="","",'Team C'!J73) | D22: =IF('Team C'!J75="","",'Team C'!J75) | E22: =IF('Team C'!J76="","",'Team C'!J76) | F22: =IF('Team C'!J77="","",'Team C'!J77) | G22: =IF('Team C'!J78="","",'Team C'!J78) | H22: =IF('Team C'!J79="","",'Team C'!J79) | I22: =IF('Team C'!J80="","",'Team C'!J80) | J22: =IF('Team C'!J81="","",'Team C'!J81) | K22: =IF('Team C'!J82="","",'Team C'!J82) | L22: =IF('Team C'!J83="","",'Team C'!J83) | M22: =IF('Team C'!J84="","",'Team C'!J84) | N22: =IF('Team C'!J92="","",'Team C'!J92) | O22: =IF(OR(B22="",D22="",E22="",N22=""),"",IF(AND(D22="PASS",E22="PASS",N22="PASS"),"YES","NO")) | P22: =IF(O22="","",IF(O22="YES",M22*1000-F22,-999999)) | Q22: =IF(P22="","",IF(P22=MAX($P$20:$P$22),"WINNER",""))
A45: Chart Team | B45: Final Value Score
A46: Team A | B46: =IF(M20="","",M20)
A47: Team B | B47: =IF(M21="","",M21)
A48: Team C | B48: =IF(M22="","",M22)
