Workbook

Sheet Team A
A1: CONSTRUCTION SITE OF THE FUTURE
A2: Human-Robot Collaboration Design Challenge
A4: TEAM A DECISION SHEET
A6: Team Name
A7: Architecture Lead
A8: Robot Engineer
A9: Cost Manager
A11: PROJECT SCENARIO
A12: Your team has been hired to plan material delivery operations for a new high-rise office building. Construction materials must move from a temporary storage area to multiple work zones. The client wants the work completed quickly, safely, and within budget. Because of labour shortages and interest in automation, your team may combine human workers and construction robots.
A17: PROJECT REQUIREMENTS
A18: Requirement | B18: Value
A19: Project Duration | B19: 5 Days
A20: Total Materials | B20: 100 Material Loads
A21: Required Capacity | B21: 20 Loads / Day
A22: Budget Limit | B22: 200 Credits
A24: TEAM ROLES
A25: Role | B25: Focus | C25: Discussion Lens
A26: Architecture Lead | B26: Worker wellbeing; safe site operation; practical implementation | C26: Can this work safely on a real site?
A27: Robot Engineer | B27: Automation; productivity; technical performance | C27: How can robots improve throughput?
A28: Cost Manager | B28: Budget control; resource efficiency | C28: Is the solution affordable and efficient?
A30: AVAILABLE RESOURCES
A31: Human Resources | B31: Cost | C31: Capacity | D31: Support Rule
A32: Construction Material Worker | B32: ='Scoring Backend'!$B$4 -> 10 | C32: ='Scoring Backend'!$C$4&" Load / Day" -> 1 Load / Day | D32: Manual material transport worker; adds 1 load/day.
A33: Robot Support Worker | B33: ='Scoring Backend'!$B$5 -> 10 | C33: 0 Loads / Day | D33: Supports robot operations; does not add direct transport capacity.
A35: Robot Resources | B35: Cost | C35: Capacity | D35: Human Support Requirement
A36: Delivery Robot | B36: ='Scoring Backend'!$B$6 -> 20 | C36: ='Scoring Backend'!$C$6&" Loads / Day" -> 3 Loads / Day | D36: 0.5 support workers per Delivery Robot
A37: Quadruped Robot | B37: ='Scoring Backend'!$B$7 -> 35 | C37: ='Scoring Backend'!$C$7&" Loads / Day" -> 5 Loads / Day | D37: 1 support worker per Quadruped Robot
A38: Multi-Robot Fleet | B38: ='Scoring Backend'!$B$8 -> 60 | C38: ='Scoring Backend'!$C$8&" Loads / Day" -> 8 Loads / Day | D38: 3 support workers per Multi-Robot Fleet
A40: ROUND 1 - COST-DRIVEN DESIGN
A41: Client Objective: deliver the project at the lowest possible cost. Select resources, then check whether the solution is feasible.
A44: Resource Selection | B44: Quantity | C44: Notes | F44: Dashboard Results | G44: Auto-Calculated
A45: Construction Material Workers | C45: Manual transport capacity | F45: Dashboard Results | G45: =$B$45*'Scoring Backend'!$C$4 + $B$47*'Scoring Backend'!$C$6 + $B$48*'Scoring Backend'!$C$7 + $B$49*'Scoring Backend'!$C$8 -> 0
A46: Robot Support Workers | C46: Dedicated support for robot operation | F46: Required Robot Support Workers | G46: =$B$47*'Scoring Backend'!$G$4 + $B$48*'Scoring Backend'!$G$5 + $B$49*'Scoring Backend'!$G$6 -> 0
A47: Delivery Robots | C47: 0.5 support workers per robot | F47: Support Worker Check | G47: =IF(COUNTA($B$45:$B$49)=0,"Status",IF($B$46>=G46,"PASS","FAIL")) -> Status
A48: Quadruped Robots | C48: 1 support worker per robot | F48: Capacity Check | G48: =IF(COUNTA($B$45:$B$49)=0,"Status",IF(G45>='Scoring Backend'!$B$20,"PASS","FAIL")) -> Status
A49: Multi-Robot Fleets | C49: 3 support workers per fleet | F49: Total Cost | G49: =$B$45*'Scoring Backend'!$B$4 + $B$46*'Scoring Backend'!$B$5 + $B$47*'Scoring Backend'!$B$6 + $B$48*'Scoring Backend'!$B$7 + $B$49*'Scoring Backend'!$B$8 -> 0
A50: Site Resource Visual | F50: Estimated Project Duration | G50: =IF(COUNT($B$45:$B$49)=0,"",IF(G45<=0,"",'Scoring Backend'!$B$19/G45))
A51: =IF(COUNT($B$45:$B$49)=0,"",REPT("👷 ",MIN(N($B$45),12))&IF(N($B$45)>12,"+","")) | B51: =IF(COUNT($B$45:$B$49)=0,"",REPT("🦺 ",MIN(N($B$46),12))&IF(N($B$46)>12,"+","")&" "&REPT("🤖 ",MIN(SUM($B$47:$B$49),12))&IF(SUM($B$47:$B$49)>12,"+","")) | C51: =IF(COUNT($B$45:$B$49)=0,"","Material Workers: "&N($B$45)&" | Support Workers: "&N($B$46)&" | Robots/Fleets: "&SUM($B$47:$B$49)) | F51: Schedule Status | G51: =IF(COUNT($B$45:$B$49)=0,"Status",IF(AND(ISNUMBER(G50),G50<='Scoring Backend'!$B$18),"ON TRACK","DELAY RISK")) -> Status
A52: Round 1 Team Discussion | F52: Capacity Target Achievement | G52: =IF(COUNT($B$45:$B$49)=0,"",REPT("█",ROUND(MIN(1,G45/'Scoring Backend'!$B$20)*20,0))&REPT("░",20-ROUND(MIN(1,G45/'Scoring Backend'!$B$20)*20,0))&" "&TEXT(G45/'Scoring Backend'!$B$20,"0%"))
A56: Round 1 Winner Rule | B56: Lowest-cost feasible solution wins.
...

Sheet Scoring Backend
A1: SCORING BACKEND - Editable Workshop Parameters
A3: Resource | B3: Cost | C3: Daily Capacity | D3: Resource Note | F3: HUMAN SUPPORT REQUIREMENTS | G3: Support Coefficient | H3: Participant Meaning
A4: Construction Material Worker | B4: 10 | C4: 1 | D4: Manual material transport worker. Directly produces transport capacity. | F4: Support Requirement per Delivery Robot | G4: 0.5 | H4: 0.5 Robot Support Workers per Delivery Robot
A5: Robot Support Worker | B5: 10 | C5: 0 | D5: Supports robot operation only; does not add manual transport capacity. | F5: Support Requirement per Quadruped Robot | G5: 1 | H5: 1 Robot Support Worker per Quadruped Robot
A6: Delivery Robot | B6: 20 | C6: 3 | D6: Robot transport capacity. | F6: Support Requirement per Multi-Robot Fleet | G6: 3 | H6: 3 Robot Support Workers per Multi-Robot Fleet
A7: Quadruped Robot | B7: 35 | C7: 5 | D7: Robot transport capacity.
A8: Multi-Robot Fleet | B8: 60 | C8: 8 | D8: Fleet transport capacity.
A11: HRC Strategy Weights | F11: Robot Type | G11: Cost / Unit | H11: Productivity Effect | I11: Safety Effect | J11: Manual Effort Effect
A12: Performance Criteria | B12: Human-Led | C12: Collaborative | D12: Robot-Led | E12: Note | F12: Delivery Robot | G12: 20 | H12: 5 | I12: 5 | J12: 8
A13: Productivity | B13: 0.4 | C13: 0.3 | D13: 0.3 | E13: Selected strategy changes weighting only | F13: Quadruped Robot | G13: 35 | H13: 10 | I13: 10 | J13: 12
A14: Operational Safety | B14: 0.3 | C14: 0.4 | D14: 0.3 | E14: No direct strategy bonus/penalty | F14: Multi-Robot Fleet | G14: 60 | H14: 18 | I14: 8 | J14: 18
A15: Manual Effort Reduction | B15: 0.3 | C15: 0.3 | D15: 0.4 | E15: Robot choices create performance effects
A17: Project Parameter | B17: Value | F17: Value Constraint | G17: Value | H17: Metric | I17: Weight | J17: Higher Means
A18: Project Duration (Days) | B18: 5 | F18: Budget Limit | G18: 200 | H18: Productivity | I18: 0.3 | J18: Faster / more efficient task execution
A19: Total Materials (Material Loads) | B19: 100 | F19: Minimum Operational Safety | G19: 70 | H19: Operational Safety | I19: 0.4 | J19: Lower accident or hazardous-event likelihood
A20: Required Capacity (Loads / Day) | B20: 20 | F20: Minimum Productivity | G20: 70 | H20: Manual Physical Effort Reduction | I20: 0.3 | J20: Less lifting, carrying, fatigue, and strain
A21: Budget Limit (Credits) | B21: 200 | F21: Minimum Manual Physical Effort Reduction | G21: 70
A22: Base Productivity Score | B22: 50 | F22: Human-Led Guidance Share | G22: 0.35 | H22: Robot Capacity Share < 35%
A23: Base Operational Safety Score | B23: 50 | F23: Collaborative Min Share | G23: 0.35 | H23: Robot Capacity Share >= 35%
A24: Base Manual Physical Effort Reduction Score | B24: 50 | F24: Collaborative Max Share | G24: 0.75 | H24: Robot Capacity Share <= 75%
F25: Robot-Led Guidance Share | G25: 0.75 | H25: Robot Capacity Share > 75%
F26: Alignment Penalty | G26: 10 | H26: Deducted from Final Value Score when Selected Strategy and Actual Operational Mode are misaligned
A27: SCORING NOTE
A28: SCORING NOTE: Team sheets use two worker pools. Construction Material Workers directly create manual transport capacity. Robot Support Workers are reserved for robot operation and only satisfy robot support requirements; they do not create manual transport capacity. Total capacity = material-worker capacity + robot capacity. Required Robot Support Workers = 0.5 × Delivery Robots + 1 × Quadruped Robots + 3 × Multi-Robot Fleets. Support check = Robot Support Workers >= Required Robot Support Workers.

Sheet Team B
A1: CONSTRUCTION SITE OF THE FUTURE
A2: Human-Robot Collaboration Design Challenge
A4: TEAM B DECISION SHEET
A6: Team Name
A7: Architecture Lead
A8: Robot Engineer
A9: Cost Manager
A11: PROJECT SCENARIO
A12: Your team has been hired to plan material delivery operations for a new high-rise office building. Construction materials must move from a temporary storage area to multiple work zones. The client wants the work completed quickly, safely, and within budget. Because of labour shortages and interest in automation, your team may combine human workers and construction robots.
A17: PROJECT REQUIREMENTS
A18: Requirement | B18: Value
A19: Project Duration | B19: 5 Days
A20: Total Materials | B20: 100 Material Loads
A21: Required Capacity | B21: 20 Loads / Day
A22: Budget Limit | B22: 200 Credits
A24: TEAM ROLES
A25: Role | B25: Focus | C25: Discussion Lens
A26: Architecture Lead | B26: Worker wellbeing; safe site operation; practical implementation | C26: Can this work safely on a real site?
A27: Robot Engineer | B27: Automation; productivity; technical performance | C27: How can robots improve throughput?
A28: Cost Manager | B28: Budget control; resource efficiency | C28: Is the solution affordable and efficient?
A30: AVAILABLE RESOURCES
A31: Human Resources | B31: Cost | C31: Capacity | D31: Support Rule
A32: Construction Material Worker | B32: ='Scoring Backend'!$B$4 -> 10 | C32: ='Scoring Backend'!$C$4&" Load / Day" -> 1 Load / Day | D32: Manual material transport worker; adds 1 load/day.
A33: Robot Support Worker | B33: ='Scoring Backend'!$B$5 -> 10 | C33: 0 Loads / Day | D33: Supports robot operations; does not add direct transport capacity.
A35: Robot Resources | B35: Cost | C35: Capacity | D35: Human Support Requirement
A36: Delivery Robot | B36: ='Scoring Backend'!$B$6 -> 20 | C36: ='Scoring Backend'!$C$6&" Loads / Day" -> 3 Loads / Day | D36: 0.5 support workers per Delivery Robot
A37: Quadruped Robot | B37: ='Scoring Backend'!$B$7 -> 35 | C37: ='Scoring Backend'!$C$7&" Loads / Day" -> 5 Loads / Day | D37: 1 support worker per Quadruped Robot
A38: Multi-Robot Fleet | B38: ='Scoring Backend'!$B$8 -> 60 | C38: ='Scoring Backend'!$C$8&" Loads / Day" -> 8 Loads / Day | D38: 3 support workers per Multi-Robot Fleet
A40: ROUND 1 - COST-DRIVEN DESIGN
A41: Client Objective: deliver the project at the lowest possible cost. Select resources, then check whether the solution is feasible.
A44: Resource Selection | B44: Quantity | C44: Notes | F44: Dashboard Results | G44: Auto-Calculated
A45: Construction Material Workers | C45: Manual transport capacity | F45: Dashboard Results | G45: =$B$45*'Scoring Backend'!$C$4 + $B$47*'Scoring Backend'!$C$6 + $B$48*'Scoring Backend'!$C$7 + $B$49*'Scoring Backend'!$C$8 -> 0
A46: Robot Support Workers | C46: Dedicated support for robot operation | F46: Required Robot Support Workers | G46: =$B$47*'Scoring Backend'!$G$4 + $B$48*'Scoring Backend'!$G$5 + $B$49*'Scoring Backend'!$G$6 -> 0
A47: Delivery Robots | C47: 0.5 support workers per robot | F47: Support Worker Check | G47: =IF(COUNTA($B$45:$B$49)=0,"Status",IF($B$46>=G46,"PASS","FAIL")) -> Status
A48: Quadruped Robots | C48: 1 support worker per robot | F48: Capacity Check | G48: =IF(COUNTA($B$45:$B$49)=0,"Status",IF(G45>='Scoring Backend'!$B$20,"PASS","FAIL")) -> Status
A49: Multi-Robot Fleets | C49: 3 support workers per fleet | F49: Total Cost | G49: =$B$45*'Scoring Backend'!$B$4 + $B$46*'Scoring Backend'!$B$5 + $B$47*'Scoring Backend'!$B$6 + $B$48*'Scoring Backend'!$B$7 + $B$49*'Scoring Backend'!$B$8 -> 0
A50: Site Resource Visual | F50: Estimated Project Duration | G50: =IF(COUNT($B$45:$B$49)=0,"",IF(G45<=0,"",'Scoring Backend'!$B$19/G45))
A51: =IF(COUNT($B$45:$B$49)=0,"",REPT("👷 ",MIN(N($B$45),12))&IF(N($B$45)>12,"+","")) | B51: =IF(COUNT($B$45:$B$49)=0,"",REPT("🦺 ",MIN(N($B$46),12))&IF(N($B$46)>12,"+","")&" "&REPT("🤖 ",MIN(SUM($B$47:$B$49),12))&IF(SUM($B$47:$B$49)>12,"+","")) | C51: =IF(COUNT($B$45:$B$49)=0,"","Material Workers: "&N($B$45)&" | Support Workers: "&N($B$46)&" | Robots/Fleets: "&SUM($B$47:$B$49)) | F51: Schedule Status | G51: =IF(COUNT($B$45:$B$49)=0,"Status",IF(AND(ISNUMBER(G50),G50<='Scoring Backend'!$B$18),"ON TRACK","DELAY RISK")) -> Status
A52: Round 1 Team Discussion | F52: Capacity Target Achievement | G52: =IF(COUNT($B$45:$B$49)=0,"",REPT("█",ROUND(MIN(1,G45/'Scoring Backend'!$B$20)*20,0))&REPT("░",20-ROUND(MIN(1,G45/'Scoring Backend'!$B$20)*20,0))&" "&TEXT(G45/'Scoring Backend'!$B$20,"0%"))
A56: Round 1 Winner Rule | B56: Lowest-cost feasible solution wins.
...

Sheet Team C
A1: CONSTRUCTION SITE OF THE FUTURE
A2: Human-Robot Collaboration Design Challenge
A4: TEAM C DECISION SHEET
A6: Team Name
A7: Architecture Lead
A8: Robot Engineer
A9: Cost Manager
A11: PROJECT SCENARIO
A12: Your team has been hired to plan material delivery operations for a new high-rise office building. Construction materials must move from a temporary storage area to multiple work zones. The client wants the work completed quickly, safely, and within budget. Because of labour shortages and interest in automation, your team may combine human workers and construction robots.
A17: PROJECT REQUIREMENTS
A18: Requirement | B18: Value
A19: Project Duration | B19: 5 Days
A20: Total Materials | B20: 100 Material Loads
A21: Required Capacity | B21: 20 Loads / Day
A22: Budget Limit | B22: 200 Credits
A24: TEAM ROLES
A25: Role | B25: Focus | C25: Discussion Lens
A26: Architecture Lead | B26: Worker wellbeing; safe site operation; practical implementation | C26: Can this work safely on a real site?
A27: Robot Engineer | B27: Automation; productivity; technical performance | C27: How can robots improve throughput?
A28: Cost Manager | B28: Budget control; resource efficiency | C28: Is the solution affordable and efficient?
A30: AVAILABLE RESOURCES
A31: Human Resources | B31: Cost | C31: Capacity | D31: Support Rule
A32: Construction Material Worker | B32: ='Scoring Backend'!$B$4 -> 10 | C32: ='Scoring Backend'!$C$4&" Load / Day" -> 1 Load / Day | D32: Manual material transport worker; adds 1 load/day.
A33: Robot Support Worker | B33: ='Scoring Backend'!$B$5 -> 10 | C33: 0 Loads / Day | D33: Supports robot operations; does not add direct transport capacity.
A35: Robot Resources | B35: Cost | C35: Capacity | D35: Human Support Requirement
A36: Delivery Robot | B36: ='Scoring Backend'!$B$6 -> 20 | C36: ='Scoring Backend'!$C$6&" Loads / Day" -> 3 Loads / Day | D36: 0.5 support workers per Delivery Robot
A37: Quadruped Robot | B37: ='Scoring Backend'!$B$7 -> 35 | C37: ='Scoring Backend'!$C$7&" Loads / Day" -> 5 Loads / Day | D37: 1 support worker per Quadruped Robot
A38: Multi-Robot Fleet | B38: ='Scoring Backend'!$B$8 -> 60 | C38: ='Scoring Backend'!$C$8&" Loads / Day" -> 8 Loads / Day | D38: 3 support workers per Multi-Robot Fleet
A40: ROUND 1 - COST-DRIVEN DESIGN
A41: Client Objective: deliver the project at the lowest possible cost. Select resources, then check whether the solution is feasible.
A44: Resource Selection | B44: Quantity | C44: Notes | F44: Dashboard Results | G44: Auto-Calculated
A45: Construction Material Workers | C45: Manual transport capacity | F45: Dashboard Results | G45: =$B$45*'Scoring Backend'!$C$4 + $B$47*'Scoring Backend'!$C$6 + $B$48*'Scoring Backend'!$C$7 + $B$49*'Scoring Backend'!$C$8 -> 0
A46: Robot Support Workers | C46: Dedicated support for robot operation | F46: Required Robot Support Workers | G46: =$B$47*'Scoring Backend'!$G$4 + $B$48*'Scoring Backend'!$G$5 + $B$49*'Scoring Backend'!$G$6 -> 0
A47: Delivery Robots | C47: 0.5 support workers per robot | F47: Support Worker Check | G47: =IF(COUNTA($B$45:$B$49)=0,"Status",IF($B$46>=G46,"PASS","FAIL")) -> Status
A48: Quadruped Robots | C48: 1 support worker per robot | F48: Capacity Check | G48: =IF(COUNTA($B$45:$B$49)=0,"Status",IF(G45>='Scoring Backend'!$B$20,"PASS","FAIL")) -> Status
A49: Multi-Robot Fleets | C49: 3 support workers per fleet | F49: Total Cost | G49: =$B$45*'Scoring Backend'!$B$4 + $B$46*'Scoring Backend'!$B$5 + $B$47*'Scoring Backend'!$B$6 + $B$48*'Scoring Backend'!$B$7 + $B$49*'Scoring Backend'!$B$8 -> 0
A50: Site Resource Visual | F50: Estimated Project Duration | G50: =IF(COUNT($B$45:$B$49)=0,"",IF(G45<=0,"",'Scoring Backend'!$B$19/G45))
A51: =IF(COUNT($B$45:$B$49)=0,"",REPT("👷 ",MIN(N($B$45),12))&IF(N($B$45)>12,"+","")) | B51: =IF(COUNT($B$45:$B$49)=0,"",REPT("🦺 ",MIN(N($B$46),12))&IF(N($B$46)>12,"+","")&" "&REPT("🤖 ",MIN(SUM($B$47:$B$49),12))&IF(SUM($B$47:$B$49)>12,"+","")) | C51: =IF(COUNT($B$45:$B$49)=0,"","Material Workers: "&N($B$45)&" | Support Workers: "&N($B$46)&" | Robots/Fleets: "&SUM($B$47:$B$49)) | F51: Schedule Status | G51: =IF(COUNT($B$45:$B$49)=0,"Status",IF(AND(ISNUMBER(G50),G50<='Scoring Backend'!$B$18),"ON TRACK","DELAY RISK")) -> Status
A52: Round 1 Team Discussion | F52: Capacity Target Achievement | G52: =IF(COUNT($B$45:$B$49)=0,"",REPT("█",ROUND(MIN(1,G45/'Scoring Backend'!$B$20)*20,0))&REPT("░",20-ROUND(MIN(1,G45/'Scoring Backend'!$B$20)*20,0))&" "&TEXT(G45/'Scoring Backend'!$B$20,"0%"))
A56: Round 1 Winner Rule | B56: Lowest-cost feasible solution wins.
...

Sheet Summary
A1: WORKSHOP SUMMARY - TEAM COMPARISON
A3: This dashboard compares Team A, Team B, and Team C. The game now separates worker allocation into Construction Material Workers and Robot Support Workers. Construction Material Workers create manual transport capacity; Robot Support Workers only support robots. Round 1 rewards the lowest-cost capacity-and-support feasible solution. Round 2 uses target value design: teams must pass core constraints first. Robot type affects Final Value Scores, while Selected HRC Strategy changes the weights used in Final Value Score.
A6: Winner Dashboard | B6: Result
A7: Round 1 Winner | B7: {=IF(COUNTIF($G$13:$G$15,"YES")=0,"No feasible team yet",INDEX($A$13:$A$15,MATCH(MAX($H$13:$H$15),$H$13:$H$15,0)))} -> No feasible team yet
A8: Round 2 Winner | B8: {=IF(COUNTIF($O$20:$O$22,"YES")=0,"No eligible team",INDEX($A$20:$A$22,MATCH(MAX($P$20:$P$22),$P$20:$P$22,0)))} -> No eligible team
A9: Round 2 Tie-Breaker | B9: Highest penalty-adjusted Final Value Score among eligible teams, then lowest cost
A12: Round 1 Comparison | B12: Net Daily Capacity | C12: Support Worker Check | D12: Capacity Check | E12: Budget Check | F12: Total Cost | G12: Feasible? | H12: Winner Score
A13: Team A | B13: ='Team A'!$G$45 -> 0 | C13: ='Team A'!$G$47 -> Status | D13: ='Team A'!$G$48 -> Status | E13: =IF(COUNTA('Team A'!$B$45:$B$49)=0,"Status",IF('Team A'!$G$49<='Scoring Backend'!$B$21,"PASS","FAIL")) -> Status | F13: ='Team A'!$G$49 -> 0 | G13: =IF(OR(C13="Status",D13="Status",E13="Status"),"Status",IF(AND(C13="PASS",D13="PASS",E13="PASS"),"YES","NO")) -> Status | H13: =IF(G13="YES",100000-F13,"")
A14: Team B | B14: ='Team B'!$G$45 -> 0 | C14: ='Team B'!$G$47 -> Status | D14: ='Team B'!$G$48 -> Status | E14: =IF(COUNTA('Team B'!$B$45:$B$49)=0,"Status",IF('Team B'!$G$49<='Scoring Backend'!$B$21,"PASS","FAIL")) -> Status | F14: ='Team B'!$G$49 -> 0 | G14: =IF(OR(C14="Status",D14="Status",E14="Status"),"Status",IF(AND(C14="PASS",D14="PASS",E14="PASS"),"YES","NO")) -> Status | H14: =IF(G14="YES",100000-F14,"")
A15: Team C | B15: ='Team C'!$G$45 -> 0 | C15: ='Team C'!$G$47 -> Status | D15: ='Team C'!$G$48 -> Status | E15: =IF(COUNTA('Team C'!$B$45:$B$49)=0,"Status",IF('Team C'!$G$49<='Scoring Backend'!$B$21,"PASS","FAIL")) -> Status | F15: ='Team C'!$G$49 -> 0 | G15: =IF(OR(C15="Status",D15="Status",E15="Status"),"Status",IF(AND(C15="PASS",D15="PASS",E15="PASS"),"YES","NO")) -> Status | H15: =IF(G15="YES",100000-F15,"")
A19: Round 2 Comparison | B19: Selected Strategy | C19: Robot Resource Share | D19: Robot Capacity Share | E19: Actual Operational Mode | F19: Strategy–Operation Alignment | G19: Net Daily Capacity | H19: Support Worker Check | I19: Capacity Check | J19: Total Cost | K19: Productivity | L19: Operational Safety | M19: Manual Physical Effort Reduction | N19: Penalty-Adjusted Final Value Score | O19: Eligible? | P19: Tie-Break Score | Q19: Winner?
A20: Team A | B20: =IF('Team A'!$B$69="","",'Team A'!$B$69) | C20: ='Team A'!$J$86 | D20: ='Team A'!$J$87 | E20: ='Team A'!$J$88 | F20: ='Team A'!$J$89 | G20: ='Team A'!$J$74 -> 0 | H20: ='Team A'!$J$76 -> Status | I20: ='Team A'!$J$77 -> Status | J20: ='Team A'!$J$78 -> 0 | K20: ='Team A'!$J$79 | L20: ='Team A'!$J$80 | M20: ='Team A'!$J$81 | N20: ='Team A'!$J$82 | O20: =IF(COUNTA('Team A'!$B$69,'Team A'!$B$73:$B$77)=0,"Status",IF(AND(I20="PASS",H20="PASS",J20<='Scoring Backend'!$G$18,K20>='Scoring Backend'!$G$20,L20>='Scoring Backend'!$G$19,M20>='Scoring Backend'!$G$21),"YES","NO")) -> Status | P20: =IF(O20="YES",N20+('Scoring Backend'!$G$18-J20)/10000,"") | Q20: =IF(AND(O20="YES",P20=MAX($P$20:$P$22)),"WINNER","")
A21: Team B | B21: =IF('Team B'!$B$69="","",'Team B'!$B$69) | C21: ='Team B'!$J$86 | D21: ='Team B'!$J$87 | E21: ='Team B'!$J$88 | F21: ='Team B'!$J$89 | G21: ='Team B'!$J$74 -> 0 | H21: ='Team B'!$J$76 -> Status | I21: ='Team B'!$J$77 -> Status | J21: ='Team B'!$J$78 -> 0 | K21: ='Team B'!$J$79 | L21: ='Team B'!$J$80 | M21: ='Team B'!$J$81 | N21: ='Team B'!$J$82 | O21: =IF(COUNTA('Team B'!$B$69,'Team B'!$B$73:$B$77)=0,"Status",IF(AND(I21="PASS",H21="PASS",J21<='Scoring Backend'!$G$18,K21>='Scoring Backend'!$G$20,L21>='Scoring Backend'!$G$19,M21>='Scoring Backend'!$G$21),"YES","NO")) -> Status | P21: =IF(O21="YES",N21+('Scoring Backend'!$G$18-J21)/10000,"") | Q21: =IF(AND(O21="YES",P21=MAX($P$20:$P$22)),"WINNER","")
A22: Team C | B22: =IF('Team C'!$B$69="","",'Team C'!$B$69) | C22: ='Team C'!$J$86 | D22: ='Team C'!$J$87 | E22: ='Team C'!$J$88 | F22: ='Team C'!$J$89 | G22: ='Team C'!$J$74 -> 0 | H22: ='Team C'!$J$76 -> Status | I22: ='Team C'!$J$77 -> Status | J22: ='Team C'!$J$78 -> 0 | K22: ='Team C'!$J$79 | L22: ='Team C'!$J$80 | M22: ='Team C'!$J$81 | N22: ='Team C'!$J$82 | O22: =IF(COUNTA('Team C'!$B$69,'Team C'!$B$73:$B$77)=0,"Status",IF(AND(I22="PASS",H22="PASS",J22<='Scoring Backend'!$G$18,K22>='Scoring Backend'!$G$20,L22>='Scoring Backend'!$G$19,M22>='Scoring Backend'!$G$21),"YES","NO")) -> Status | P22: =IF(O22="YES",N22+('Scoring Backend'!$G$18-J22)/10000,"") | Q22: =IF(AND(O22="YES",P22=MAX($P$20:$P$22)),"WINNER","")
A44: Chart Team | B44: Penalty-Adjusted Final Value Score
A45: Team A | B45: =N20
A46: Team B | B46: =N21
A47: Team C | B47: =N22
B48: =N23 -> 0

Sheet Formula Tests
A1: Test | B1: Expected logic | C1: Formula / Link | D1: Status | E1: Notes
A2: Round 1 capacity | B2: material workers + robot capacity | C2: ='Team A'!G45 -> 0 | D2: Check after input | E2: B45 material, B46 support, B47:B49 robots
A3: Round 1 support | B3: support workers >= robot support load | C3: ='Team A'!G47 -> Status | D3: Check after input | E3: B46 compared with G46
A4: Round 2 capacity | B4: material workers + robot capacity | C4: ='Team A'!J74 -> 0 | D4: Check after input | E4: B73 material, B74 support, B75:B77 robots
A5: Round 2 support | B5: support workers >= robot support load | C5: ='Team A'!J76 -> Status | D5: Check after input | E5: B74 compared with J75
A6: Team recommendation section | B6: Only final one-sentence recommendation remains | C6: Team sheets A99 only | D6: OK
